[2024-07-27 23:14:33,399: INFO: _internal: [31m[1mWARNING: This is a development server. Do not use it in a production deployment. Use a production WSGI server instead.[0m
 * Running on all addresses (0.0.0.0)
 * Running on http://127.0.0.1:80
 * Running on http://192.168.253.230:80]
[2024-07-27 23:14:33,399: INFO: _internal: [33mPress CTRL+C to quit[0m]
[2024-07-27 23:15:09,149: INFO: _internal: 127.0.0.1 - - [27/Jul/2024 23:15:09] "GET / HTTP/1.1" 200 -]
[2024-07-27 23:15:27,500: ERROR: app: Exception on /predict [POST]]
Traceback (most recent call last):
  File "C:\Users\Amol\.conda\envs\cnncls\lib\site-packages\flask\app.py", line 1473, in wsgi_app
    response = self.full_dispatch_request()
  File "C:\Users\Amol\.conda\envs\cnncls\lib\site-packages\flask\app.py", line 882, in full_dispatch_request
    rv = self.handle_user_exception(e)
  File "C:\Users\Amol\.conda\envs\cnncls\lib\site-packages\flask_cors\extension.py", line 178, in wrapped_function
    return cors_after_request(app.make_response(f(*args, **kwargs)))
  File "C:\Users\Amol\.conda\envs\cnncls\lib\site-packages\flask\app.py", line 880, in full_dispatch_request
    rv = self.dispatch_request()
  File "C:\Users\Amol\.conda\envs\cnncls\lib\site-packages\flask\app.py", line 865, in dispatch_request
    return self.ensure_sync(self.view_functions[rule.endpoint])(**view_args)  # type: ignore[no-any-return]
  File "C:\Users\Amol\.conda\envs\cnncls\lib\site-packages\flask_cors\decorator.py", line 130, in wrapped_function
    resp = make_response(f(*args, **kwargs))
  File "app.py", line 40, in predictRoute
    result = clApp.classifier.predict()
  File "c:\users\amol\onedrive\documents\chicken-disease-classification-projects-main\src\cnnClassifier\pipeline\predict.py", line 16, in predict
    model = load_model(os.path.join("artifacts","training", "model.h5"))
  File "C:\Users\Amol\.conda\envs\cnncls\lib\site-packages\keras\src\saving\saving_api.py", line 238, in load_model
    return legacy_sm_saving_lib.load_model(
  File "C:\Users\Amol\.conda\envs\cnncls\lib\site-packages\keras\src\utils\traceback_utils.py", line 70, in error_handler
    raise e.with_traceback(filtered_tb) from None
  File "C:\Users\Amol\.conda\envs\cnncls\lib\site-packages\keras\src\saving\legacy\save.py", line 234, in load_model
    raise IOError(
OSError: No file or directory found at artifacts\training\model.h5
[2024-07-27 23:15:27,502: INFO: _internal: 127.0.0.1 - - [27/Jul/2024 23:15:27] "[35m[1mPOST /predict HTTP/1.1[0m" 500 -]
